Workbook
Name Slicer_Diabets_Status: #N/A
Name Slicer_smoker1: #N/A
Name Slicer_Weight_Status: #N/A

Sheet Hospitalisation Details
A1: Customer ID | B1: year | C1: month | D1: date | E1: children | F1: charges | G1: Hospital tier | H1: City tier | I1: State ID | J1: Date Of Birth | K1: Age | M1: Missing Values
A2: Id2335 | B2: 1992 | C2: Jul | D2: 9 | E2: 0 | F2: 563.84 | G2: tier - 2 | H2: tier - 3 | I2: R1013 | J2: =CONCATENATE(D2,"-",C2,"-",B2) -> 9-Jul-1992 | K2: =YEARFRAC(J2,L$17) -> 30.913889 | O2: Id1
A3: Id2334 | B3: 1992 | C3: Nov | D3: 30 | E3: 0 | F3: 570.62 | G3: tier - 2 | H3: tier - 1 | I3: R1013 | J3: =CONCATENATE(D3,"-",C3,"-",B3) -> 30-Nov-1992 | K3: =YEARFRAC(J3,L$17) -> 30.522222 | L3: Number of missing values filled with ? in the Column CustomerID | M3: =COUNTIF(A2:A2344,"?") -> 6 | O3: Id2
A4: Id2333 | B4: 1993 | C4: Jun | D4: 30 | E4: 0 | F4: 600 | G4: tier - 2 | H4: tier - 1 | I4: R1013 | J4: =CONCATENATE(D4,"-",C4,"-",B4) -> 30-Jun-1993 | K4: =YEARFRAC(J4,L$17) -> 29.938889 | L4: Number of missing values filled with ? in the Column year | M4: =COUNTIF(B2:B2344,"?") -> 0 | O4: Id3
A5: Id2332 | B5: 1992 | C5: Sep | D5: 13 | E5: 0 | F5: 604.54 | G5: tier - 3 | H5: tier - 3 | I5: R1013 | J5: =CONCATENATE(D5,"-",C5,"-",B5) -> 13-Sep-1992 | K5: =YEARFRAC(J5,L$17) -> 30.736111 | L5: Number of missing values filled with ? in the Column month | M5: =COUNTIF(C2:C2344,"?") -> 0 | O5: Id4
A6: Id2331 | B6: 1998 | C6: Jul | D6: 27 | E6: 0 | F6: 637.26 | G6: tier - 3 | H6: tier - 3 | I6: R1013 | J6: =CONCATENATE(D6,"-",C6,"-",B6) -> 27-Jul-1998 | K6: =YEARFRAC(J6,L$17) -> 24.863889 | L6: Number of missing values filled with ? in the Column date | M6: =COUNTIF(D2:D2344,"?") -> 0 | O6: Id5
A7: Id2330 | B7: 2001 | C7: Nov | D7: 20 | E7: 0 | F7: 646.14 | G7: tier - 3 | H7: tier - 3 | I7: R1012 | J7: =CONCATENATE(D7,"-",C7,"-",B7) -> 20-Nov-2001 | K7: =YEARFRAC(J7,L$17) -> 21.55 | L7: Number of missing values filled with ? in the Column children | M7: =COUNTIF(E2:E2344,"?") -> 0 | O7: Id6
A8: Id2329 | B8: 1993 | C8: Jun | D8: 1 | E8: 0 | F8: 650 | G8: tier - 3 | H8: tier - 3 | I8: R1013 | J8: =CONCATENATE(D8,"-",C8,"-",B8) -> 1-Jun-1993 | K8: =YEARFRAC(J8,L$17) -> 30.019444 | L8: Number of missing values filled with ? in the Column charges | M8: =COUNTIF(F2:F2344,"?") -> 0 | O8: Id7
A9: Id2328 | B9: 1995 | C9: Jul | D9: 4 | E9: 0 | F9: 650 | G9: tier - 3 | H9: tier - 3 | I9: R1013 | J9: =CONCATENATE(D9,"-",C9,"-",B9) -> 4-Jul-1995 | K9: =YEARFRAC(J9,L$17) -> 27.927778 | L9: Number of missing values filled with ? in the Column Hospiatal tier | M9: =COUNTIF(G2:G234,"?") -> 0 | O9: Id8
A10: Id2327 | B10: 2002 | C10: Nov | D10: 29 | E10: 0 | F10: 668 | G10: tier - 3 | H10: tier - 2 | I10: R1012 | J10: =CONCATENATE(D10,"-",C10,"-",B10) -> 29-Nov-2002 | K10: =YEARFRAC(J10,L$17) -> 20.525 | L10: Number of missing values filled with ? in the Column City tier | M10: =COUNTIF(H2:H2344,"?") -> 0 | O10: Id9
A11: Id2326 | B11: 1997 | C11: Nov | D11: 9 | E11: 0 | F11: 670 | G11: tier - 3 | H11: tier - 3 | I11: R1013 | J11: =CONCATENATE(D11,"-",C11,"-",B11) -> 9-Nov-1997 | K11: =YEARFRAC(J11,L$17) -> 25.580556 | L11: Number of missing values filled with ? in the Column State ID | M11: =COUNTIF(I3:I2344,"?") -> 0 | O11: Id10
A12: Id2325 | B12: 2001 | C12: Sep | D12: 12 | E12: 0 | F12: 687.54 | G12: tier - 3 | H12: tier - 2 | I12: R1013 | J12: =CONCATENATE(D12,"-",C12,"-",B12) -> 12-Sep-2001 | K12: =YEARFRAC(J12,L$17) -> 21.738889 | O12: Id11
A13: Id2324 | B13: 1999 | C13: Dec | D13: 26 | E13: 0 | F13: 700 | G13: tier - 2 | H13: tier - 3 | I13: R1013 | J13: =CONCATENATE(D13,"-",C13,"-",B13) -> 26-Dec-1999 | K13: =YEARFRAC(J13,L$17) -> 23.45 | L13: Most occuring value in the hospital Tier | M13: {=INDEX(G2:G2344,MODE(MATCH(G2:G2344,G2:G2344,0)))} -> tier - 2 | O13: Id12
A14: Id2323 | B14: 1999 | C14: Dec | D14: 14 | E14: 0 | F14: 722.99 | G14: tier - 3 | H14: tier - 1 | I14: R1013 | J14: =CONCATENATE(D14,"-",C14,"-",B14) -> 14-Dec-1999 | K14: =YEARFRAC(J14,L$17) -> 23.483333 | L14: Most occuring value in the city tier | M14: {=INDEX(H2:H2344,MODE(MATCH(H2:H2344,H2:H2344,0)))} -> tier - 2 | O14: Id13
A15: Id2322 | B15: 2002 | C15: Sep | D15: 19 | E15: 0 | F15: 750 | G15: tier - 3 | H15: tier - 1 | I15: R1012 | J15: =CONCATENATE(D15,"-",C15,"-",B15) -> 19-Sep-2002 | K15: =YEARFRAC(J15,L$17) -> 20.719444 | O15: Id14
A16: Id2321 | B16: 1993 | C16: Aug | D16: 9 | E16: 0 | F16: 760 | G16: tier - 3 | H16: tier - 1 | I16: R1013 | J16: =CONCATENATE(D16,"-",C16,"-",B16) -> 9-Aug-1993 | K16: =YEARFRAC(J16,L$17) -> 29.830556 | O16: Id15
A17: Id2320 | B17: 1996 | C17: Oct | D17: 22 | E17: 0 | F17: 760 | G17: tier - 3 | H17: tier - 3 | I17: R1013 | J17: =CONCATENATE(D17,"-",C17,"-",B17) -> 22-Oct-1996 | K17: =YEARFRAC(J17,L$17) -> 26.627778 | L17: 45085 | O17: Id16
A18: Id2319 | B18: 1993 | C18: Jun | D18: 28 | E18: 0 | F18: 770 | G18: tier - 3 | H18: tier - 3 | I18: R1013 | J18: =CONCATENATE(D18,"-",C18,"-",B18) -> 28-Jun-1993 | K18: =YEARFRAC(J18,L$17) -> 29.944444 | O18: Id17
A19: Id2318 | B19: 1996 | C19: Sep | D19: 18 | E19: 0 | F19: 770.38 | G19: tier - 3 | H19: tier - 2 | I19: R1012 | J19: =CONCATENATE(D19,"-",C19,"-",B19) -> 18-Sep-1996 | K19: =YEARFRAC(J19,L$17) -> 26.722222 | O19: Id18
A20: Id2317 | B20: 1995 | C20: Dec | D20: 7 | E20: 0 | F20: 773.54 | G20: tier - 3 | H20: tier - 2 | I20: R1013 | J20: =CONCATENATE(D20,"-",C20,"-",B20) -> 7-Dec-1995 | K20: =YEARFRAC(J20,L$17) -> 27.502778 | O20: Id19
A21: Id2316 | B21: 2004 | C21: Oct | D21: 7 | E21: 0 | F21: 830.52 | G21: tier - 3 | H21: tier - 2 | I21: R1011 | J21: =CONCATENATE(D21,"-",C21,"-",B21) -> 7-Oct-2004 | K21: =YEARFRAC(J21,L$17) -> 18.669444 | O21: Id20
A22: Id2315 | B22: 2000 | C22: Nov | D22: 18 | E22: 0 | F22: 865.41 | G22: tier - 3 | H22: tier - 1 | I22: R1013 | J22: =CONCATENATE(D22,"-",C22,"-",B22) -> 18-Nov-2000 | K22: =YEARFRAC(J22,L$17) -> 22.555556 | O22: Id21
A23: Id2314 | B23: 1993 | C23: Nov | D23: 27 | E23: 0 | F23: 896.21 | G23: tier - 3 | H23: tier - 1 | I23: R1013 | J23: =CONCATENATE(D23,"-",C23,"-",B23) -> 27-Nov-1993 | K23: =YEARFRAC(J23,L$17) -> 29.530556 | O23: Id22
A24: Id2313 | B24: 1994 | C24: Oct | D24: 30 | E24: 0 | F24: 915.07 | G24: tier - 3 | H24: tier - 1 | I24: R1013 | J24: =CONCATENATE(D24,"-",C24,"-",B24) -> 30-Oct-1994 | K24: =YEARFRAC(J24,L$17) -> 28.605556 | O24: Id23
A25: Id2312 | B25: 1995 | C25: Oct | D25: 28 | E25: 0 | F25: 928.59 | G25: tier - 3 | H25: tier - 1 | I25: R1013 | J25: =CONCATENATE(D25,"-",C25,"-",B25) -> 28-Oct-1995 | K25: =YEARFRAC(J25,L$17) -> 27.611111 | O25: Id24
A26: Id2311 | B26: 2001 | C26: Aug | D26: 19 | E26: 0 | F26: 964.71 | G26: tier - 3 | H26: tier - 2 | I26: R1013 | J26: =CONCATENATE(D26,"-",C26,"-",B26) -> 19-Aug-2001 | K26: =YEARFRAC(J26,L$17) -> 21.802778 | O26: Id25
A27: Id2310 | B27: 1994 | C27: Nov | D27: 22 | E27: 0 | F27: 1006.65 | G27: tier - 3 | H27: tier - 2 | I27: R1013 | J27: =CONCATENATE(D27,"-",C27,"-",B27) -> 22-Nov-1994 | K27: =YEARFRAC(J27,L$17) -> 28.544444 | O27: Id26
A28: Id2309 | B28: 2000 | C28: Oct | D28: 9 | E28: 0 | F28: 1012 | G28: tier - 3 | H28: tier - 2 | I28: R1013 | J28: =CONCATENATE(D28,"-",C28,"-",B28) -> 9-Oct-2000 | K28: =YEARFRAC(J28,L$17) -> 22.663889 | O28: Id27
A29: Id2308 | B29: 1999 | C29: Aug | D29: 5 | E29: 0 | F29: 1019 | G29: tier - 3 | H29: tier - 2 | I29: R1013 | J29: =CONCATENATE(D29,"-",C29,"-",B29) -> 5-Aug-1999 | K29: =YEARFRAC(J29,L$17) -> 23.841667 | O29: Id28
... A1173: Id1167 | B1173: 1970 | C1173: Sep | D1173: 30 | E1173: 0 | F1173: 9634.54 | G1173: tier - 2 | H1173: tier - 2 | I1173: R1011 | J1173: =CONCATENATE(D1173,"-",C1173,"-",B1173) -> 30-Sep-1970 | K1173: =YEARFRAC(J1173,L$17) -> 52.688889 | O1173: Id1172
A1174: Id1166 | B1174: 1971 | C1174: Jul | D1174: 19 | E1174: 0 | F1174: 9644.25 | G1174: tier - 2 | H1174: tier - 1 | I1174: R1012 | J1174: =CONCATENATE(D1174,"-",C1174,"-",B1174) -> 19-Jul-1971 | K1174: =YEARFRAC(J1174,L$17) -> 51.886111
A1175: Id1165 | B1175: 1974 | C1175: Jul | D1175: 8 | E1175: 0 | F1175: 9653.81 | G1175: tier - 2 | H1175: tier - 2 | I1175: R1011 | J1175: =CONCATENATE(D1175,"-",C1175,"-",B1175) -> 8-Jul-1974 | K1175: =YEARFRAC(J1175,L$17) -> 48.916667
A1176: Id1164 | B1176: 1981 | C1176: Aug | D1176: 8 | E1176: 1 | F1176: 9664.34 | G1176: tier - 2 | H1176: tier - 3 | I1176: R1011 | J1176: =CONCATENATE(D1176,"-",C1176,"-",B1176) -> 8-Aug-1981 | K1176: =YEARFRAC(J1176,L$17) -> 41.833333
A1177: Id1163 | B1177: 1966 | C1177: Sep | D1177: 16 | E1177: 0 | F1177: 9684.29 | G1177: tier - 3 | H1177: tier - 2 | I1177: R1013 | J1177: =CONCATENATE(D1177,"-",C1177,"-",B1177) -> 16-Sep-1966 | K1177: =YEARFRAC(J1177,L$17) -> 56.727778
A1178: Id1162 | B1178: 1964 | C1178: Nov | D1178: 7 | E1178: 0 | F1178: 9698.42 | G1178: tier - 3 | H1178: tier - 3 | I1178: R1013 | J1178: =CONCATENATE(D1178,"-",C1178,"-",B1178) -> 7-Nov-1964 | K1178: =YEARFRAC(J1178,L$17) -> 58.586111
A1179: Id1161 | B1179: 1977 | C1179: Sep | D1179: 19 | E1179: 3 | F1179: 9704.67 | G1179: tier - 2 | H1179: tier - 3 | I1179: R1024 | J1179: =CONCATENATE(D1179,"-",C1179,"-",B1179) -> 19-Sep-1977 | K1179: =YEARFRAC(J1179,L$17) -> 45.719444
A1180: Id1160 | B1180: 1972 | C1180: Jul | D1180: 10 | E1180: 0 | F1180: 9710.71 | G1180: tier - 2 | H1180: tier - 1 | I1180: R1021 | J1180: =CONCATENATE(D1180,"-",C1180,"-",B1180) -> 10-Jul-1972 | K1180: =YEARFRAC(J1180,L$17) -> 50.911111
A1181: Id1159 | B1181: 1975 | C1181: Jun | D1181: 27 | E1181: 2 | F1181: 9715.84 | G1181: tier - 2 | H1181: tier - 1 | I1181: R1024 | J1181: =CONCATENATE(D1181,"-",C1181,"-",B1181) -> 27-Jun-1975 | K1181: =YEARFRAC(J1181,L$17) -> 47.947222
A1182: Id1158 | B1182: 1970 | C1182: Sep | D1182: 12 | E1182: 0 | F1182: 9722.77 | G1182: tier - 3 | H1182: tier - 1 | I1182: R1016 | J1182: =CONCATENATE(D1182,"-",C1182,"-",B1182) -> 12-Sep-1970 | K1182: =YEARFRAC(J1182,L$17) -> 52.738889
A1183: Id1157 | B1183: 1970 | C1183: Aug | D1183: 18 | E1183: 1 | F1183: 9724.53 | G1183: tier - 3 | H1183: tier - 1 | I1183: R1011 | J1183: =CONCATENATE(D1183,"-",C1183,"-",B1183) -> 18-Aug-1970 | K1183: =YEARFRAC(J1183,L$17) -> 52.805556
...

Sheet Customer Names
A1: Customer ID | B1: First Name | C1: Title | D1: Last Name
A2: Id1 | B2: Hawks | C2: Ms | D2: Kelly
A3: Id2 | B3: Lehner | C3: Mr | D3: Matthew D
A4: Id3 | B4: Lu | C4: Mr | D4: Phil
A5: Id4 | B5: Osborne | C5: Ms | D5: Kelsey
A6: Id5 | B6: Kadala | C6: Ms | D6: Kristyn
A7: Id6 | B7: Baker | C7: Mr | D7: Russell B
A8: Id7 | B8: Macpherson | C8: Mr | D8: Scott
A9: Id8 | B9: Hallman | C9: Mr | D9: Stephen
A10: Id9 | B10: Moran | C10: Mr | D10: Patrick R
A11: Id10 | B11: Benner | C11: Ms | D11: Brooke N
A12: Id11 | B12: Fierro Vargas | C12: Ms | D12: Paola Andrea
... A72: Id71 | B72: Turner | C72: Mr | D72: Jeff
A73: Id72 | B73: Rangel | C73: Mr | D73: Elenilton V | E73: Sr
A74: Id73 | B74: Lacey | C74: Ms | D74: Maurya
A75: Id74 | B75: Stiger | C75: Ms | D75: Samantha C
A76: Id75 | B76: Caldwell | C76: Ms | D76: Bethany A
A77: Id76 | B77: Marmillod | C77: Mr | D77: Yves
A78: Id77 | B78: Cloutier-Simons | C78: Ms | D78: Danielle
A79: Id78 | B79: Vegas | C79: Ms | D79: Julia
A80: Id79 | B80: Cochran | C80: Mr | D80: Joshua
A81: Id80 | B81: Holtzapple | C81: Ms | D81: Jennifer
A82: Id81 | B82: Meyer | C82: Ms | D82: Gwen M
A83: Id82 | B83: Brickley | C83: Mr | D83: Patrick
A84: Id83 | B84: Magee | C84: Ms | D84: Kate
A85: Id84 | B85: Thoma | C85: Mr | D85: Kevin
... A188: Id187 | B188: Dublin | C188: Mr | D188: Andrew P
A189: Id188 | B189: Cleland | C189: Mr | D189: George M | E189: V
A190: Id189 | B190: Evans | C190: Ms | D190: Sarah
A191: Id190 | B191: Boyd | C191: Ms | D191: Lara
A192: Id191 | B192: Roulier | C192: Mr | D192: Sebastien
A193: Id192 | B193: Mullins | C193: Mr | D193: Padraig
A194: Id193 | B194: Hofmann | C194: Ms | D194: Heather
A195: Id194 | B195: Garcia Garcia | C195: Mr | D195: Jorge
A196: Id195 | B196: Klecker | C196: Mr | D196: Jack R
A197: Id196 | B197: Cancre | C197: Mr | D197: Felix
A198: Id197 | B198: Denucci | C198: Mr | D198: Christopher C
A199: Id198 | B199: Saldana | C199: Mr | D199: Jesse
A200: Id199 | B200: Weinberg | C200: Ms | D200: Jill
A201: Id200 | B201: Walsh | C201: Mr | D201: William
...

Sheet Medical Examinations
A1: Customer ID | B1: BMI | C1: HBA1C | D1: Heart Issues | E1: Any Transplants | F1: Cancer history | G1: NumberOfMajorSurgeries | H1: smoker | I1: Weight Status | J1: Diabets Status | L1: MissingValues
A2: Id1 | B2: 47.41 | C2: 7.47 | D2: No | E2: No | F2: No | G2: 0 | H2: Yes | I2: =IF(B2<18.5,"under Weight",IF(B2<=24.9,"Normal Weight",IF(B2<=29.9,"Over Weight","Obesity"))) -> Obesity | J2: =IF(C2<5.7,"Normal",IF(C2<=6.4,"Prediabetes","Diabetes")) -> Diabetes | K2: Number of missing values filled with ? in the Column CustomerID | L2: =COUNTIF(A2:A2336,"?") -> 0
A3: Id2 | B3: 30.36 | C3: 5.77 | D3: No | E3: No | F3: No | G3: 0 | H3: Yes | I3: =IF(B3<18.5,"under Weight",IF(B3<=24.9,"Normal Weight",IF(B3<=29.9,"Over Weight","Obesity"))) -> Obesity | J3: =IF(C3<5.7,"Normal",IF(C3<=6.4,"Prediabetes","Diabetes")) -> Prediabetes | K3: Number of missing values filled with ? in the Column BMI | L3: =COUNTIF(B2:B2336,"?") -> 0
A4: Id3 | B4: 34.485 | C4: 11.87 | D4: Yes | E4: No | F4: No | G4: 2 | H4: Yes | I4: =IF(B4<18.5,"under Weight",IF(B4<=24.9,"Normal Weight",IF(B4<=29.9,"Over Weight","Obesity"))) -> Obesity | J4: =IF(C4<5.7,"Normal",IF(C4<=6.4,"Prediabetes","Diabetes")) -> Diabetes | K4: Number of missing values filled with ? in the Column HBAIC | L4: =COUNTIF(C2:C2336,"?") -> 0
A5: Id4 | B5: 38.095 | C5: 6.05 | D5: No | E5: No | F5: No | G5: 0 | H5: Yes | I5: =IF(B5<18.5,"under Weight",IF(B5<=24.9,"Normal Weight",IF(B5<=29.9,"Over Weight","Obesity"))) -> Obesity | J5: =IF(C5<5.7,"Normal",IF(C5<=6.4,"Prediabetes","Diabetes")) -> Prediabetes | K5: Number of missing values filled with ? in the Column Heart Issues | L5: =COUNTIF(D2:D2336,"?") -> 0
A6: Id5 | B6: 35.53 | C6: 5.45 | D6: No | E6: No | F6: No | G6: 0 | H6: Yes | I6: =IF(B6<18.5,"under Weight",IF(B6<=24.9,"Normal Weight",IF(B6<=29.9,"Over Weight","Obesity"))) -> Obesity | J6: =IF(C6<5.7,"Normal",IF(C6<=6.4,"Prediabetes","Diabetes")) -> Normal | K6: Number of missing values filled with ? in the Column Any Tramsplants | L6: =COUNTIF(E2:E2336,"?") -> 0
A7: Id6 | B7: 32.8 | C7: 6.59 | D7: No | E7: No | F7: No | G7: 0 | H7: Yes | I7: =IF(B7<18.5,"under Weight",IF(B7<=24.9,"Normal Weight",IF(B7<=29.9,"Over Weight","Obesity"))) -> Obesity | J7: =IF(C7<5.7,"Normal",IF(C7<=6.4,"Prediabetes","Diabetes")) -> Diabetes | K7: Number of missing values filled with ? in the Column Cancer History | L7: =COUNTIF(F2:F2336,"?") -> 0
A8: Id7 | B8: 36.4 | C8: 6.07 | D8: No | E8: No | F8: No | G8: 0 | H8: Yes | I8: =IF(B8<18.5,"under Weight",IF(B8<=24.9,"Normal Weight",IF(B8<=29.9,"Over Weight","Obesity"))) -> Obesity | J8: =IF(C8<5.7,"Normal",IF(C8<=6.4,"Prediabetes","Diabetes")) -> Prediabetes | K8: Number of missing values filled with ? in the Column NumberOfMajorSurgerios | L8: =COUNTIF(G2:G2336,"?") -> 0
A9: Id8 | B9: 36.96 | C9: 7.93 | D9: No | E9: No | F9: No | G9: 3 | H9: Yes | I9: =IF(B9<18.5,"under Weight",IF(B9<=24.9,"Normal Weight",IF(B9<=29.9,"Over Weight","Obesity"))) -> Obesity | J9: =IF(C9<5.7,"Normal",IF(C9<=6.4,"Prediabetes","Diabetes")) -> Diabetes | K9: Number of missing values filled with ? in the Column Smoker | L9: =COUNTIF(H2:H2336,"?") -> 0
A10: Id9 | B10: 41.14 | C10: 9.58 | D10: Yes | E10: No | F10: Yes | G10: 1 | H10: Yes | I10: =IF(B10<18.5,"under Weight",IF(B10<=24.9,"Normal Weight",IF(B10<=29.9,"Over Weight","Obesity"))) -> Obesity | J10: =IF(C10<5.7,"Normal",IF(C10<=6.4,"Prediabetes","Diabetes")) -> Diabetes
A11: Id10 | B11: 38.06 | C11: 10.79 | D11: No | E11: No | F11: No | G11: 0 | H11: Yes | I11: =IF(B11<18.5,"under Weight",IF(B11<=24.9,"Normal Weight",IF(B11<=29.9,"Over Weight","Obesity"))) -> Obesity | J11: =IF(C11<5.7,"Normal",IF(C11<=6.4,"Prediabetes","Diabetes")) -> Diabetes | K11: Most occuring value in the Smoker column | L11: {=INDEX(H2:H2336,MODE(MATCH(H2:H233,H2:H2336,0)))} -> Yes
A12: Id11 | B12: 37.7 | C12: 5.96 | D12: Yes | E12: No | F12: No | G12: 2 | H12: Yes | I12: =IF(B12<18.5,"under Weight",IF(B12<=24.9,"Normal Weight",IF(B12<=29.9,"Over Weight","Obesity"))) -> Obesity | J12: =IF(C12<5.7,"Normal",IF(C12<=6.4,"Prediabetes","Diabetes")) -> Prediabetes
A13: Id12 | B13: 42.13 | C13: 11.9 | D13: No | E13: No | F13: No | G13: 0 | H13: Yes | I13: =IF(B13<18.5,"under Weight",IF(B13<=24.9,"Normal Weight",IF(B13<=29.9,"Over Weight","Obesity"))) -> Obesity | J13: =IF(C13<5.7,"Normal",IF(C13<=6.4,"Prediabetes","Diabetes")) -> Diabetes | K13: Data transformation
A14: Id13 | B14: 40.92 | C14: 8.41 | D14: No | E14: No | F14: No | G14: 0 | H14: Yes | I14: =IF(B14<18.5,"under Weight",IF(B14<=24.9,"Normal Weight",IF(B14<=29.9,"Over Weight","Obesity"))) -> Obesity | J14: =IF(C14<5.7,"Normal",IF(C14<=6.4,"Prediabetes","Diabetes")) -> Diabetes | K14: 3.For cosistency standerdize both columns to same format
A15: Id14 | B15: 40.565 | C15: 7.02 | D15: No | E15: No | F15: No | G15: 0 | H15: Yes | I15: =IF(B15<18.5,"under Weight",IF(B15<=24.9,"Normal Weight",IF(B15<=29.9,"Over Weight","Obesity"))) -> Obesity | J15: =IF(C15<5.7,"Normal",IF(C15<=6.4,"Prediabetes","Diabetes")) -> Diabetes
A16: Id15 | B16: 36.385 | C16: 7.59 | D16: Yes | E16: No | F16: No | G16: 2 | H16: Yes | I16: =IF(B16<18.5,"under Weight",IF(B16<=24.9,"Normal Weight",IF(B16<=29.9,"Over Weight","Obesity"))) -> Obesity | J16: =IF(C16<5.7,"Normal",IF(C16<=6.4,"Prediabetes","Diabetes")) -> Diabetes
A17: Id16 | B17: 39.9 | C17: 11.32 | D17: No | E17: No | F17: No | G17: 0 | H17: Yes | I17: =IF(B17<18.5,"under Weight",IF(B17<=24.9,"Normal Weight",IF(B17<=29.9,"Over Weight","Obesity"))) -> Obesity | J17: =IF(C17<5.7,"Normal",IF(C17<=6.4,"Prediabetes","Diabetes")) -> Diabetes | K17: Below 5.7 5.7 – 6.4 Normal Prediabetes 6.5 and Above Diabetes
A18: Id17 | B18: 33.8 | C18: 7.67 | D18: No | E18: No | F18: No | G18: 3 | H18: Yes | I18: =IF(B18<18.5,"under Weight",IF(B18<=24.9,"Normal Weight",IF(B18<=29.9,"Over Weight","Obesity"))) -> Obesity | J18: =IF(C18<5.7,"Normal",IF(C18<=6.4,"Prediabetes","Diabetes")) -> Diabetes
A19: Id18 | B19: 36.765 | C19: 7.29 | D19: Yes | E19: No | F19: Yes | G19: 1 | H19: Yes | I19: =IF(B19<18.5,"under Weight",IF(B19<=24.9,"Normal Weight",IF(B19<=29.9,"Over Weight","Obesity"))) -> Obesity | J19: =IF(C19<5.7,"Normal",IF(C19<=6.4,"Prediabetes","Diabetes")) -> Diabetes
A20: Id19 | B20: 36.955 | C20: 4.72 | D20: Yes | E20: No | F20: No | G20: 1 | H20: Yes | I20: =IF(B20<18.5,"under Weight",IF(B20<=24.9,"Normal Weight",IF(B20<=29.9,"Over Weight","Obesity"))) -> Obesity | J20: =IF(C20<5.7,"Normal",IF(C20<=6.4,"Prediabetes","Diabetes")) -> Normal
A21: Id20 | B21: 42.9 | C21: 11.41 | D21: No | E21: No | F21: No | G21: 0 | H21: Yes | I21: =IF(B21<18.5,"under Weight",IF(B21<=24.9,"Normal Weight",IF(B21<=29.9,"Over Weight","Obesity"))) -> Obesity | J21: =IF(C21<5.7,"Normal",IF(C21<=6.4,"Prediabetes","Diabetes")) -> Diabetes
A22: Id21 | B22: 36.3 | C22: 11.5 | D22: Yes | E22: No | F22: No | G22: 2 | H22: Yes | I22: =IF(B22<18.5,"under Weight",IF(B22<=24.9,"Normal Weight",IF(B22<=29.9,"Over Weight","Obesity"))) -> Obesity | J22: =IF(C22<5.7,"Normal",IF(C22<=6.4,"Prediabetes","Diabetes")) -> Diabetes
A23: Id22 | B23: 32.2 | C23: 6.22 | D23: Yes | E23: No | F23: No | G23: 2 | H23: Yes | I23: =IF(B23<18.5,"under Weight",IF(B23<=24.9,"Normal Weight",IF(B23<=29.9,"Over Weight","Obesity"))) -> Obesity | J23: =IF(C23<5.7,"Normal",IF(C23<=6.4,"Prediabetes","Diabetes")) -> Prediabetes
A24: Id23 | B24: 31.3 | C24: 11.38 | D24: No | E24: No | F24: No | G24: 3 | H24: Yes | I24: =IF(B24<18.5,"under Weight",IF(B24<=24.9,"Normal Weight",IF(B24<=29.9,"Over Weight","Obesity"))) -> Obesity | J24: =IF(C24<5.7,"Normal",IF(C24<=6.4,"Prediabetes","Diabetes")) -> Diabetes
A25: Id24 | B25: 41.8 | C25: 7.89 | D25: Yes | E25: No | F25: No | G25: 2 | H25: Yes | I25: =IF(B25<18.5,"under Weight",IF(B25<=24.9,"Normal Weight",IF(B25<=29.9,"Over Weight","Obesity"))) -> Obesity | J25: =IF(C25<5.7,"Normal",IF(C25<=6.4,"Prediabetes","Diabetes")) -> Diabetes
A26: Id25 | B26: 35.09 | C26: 4.38 | D26: Yes | E26: No | F26: No | G26: 2 | H26: Yes | I26: =IF(B26<18.5,"under Weight",IF(B26<=24.9,"Normal Weight",IF(B26<=29.9,"Over Weight","Obesity"))) -> Obesity | J26: =IF(C26<5.7,"Normal",IF(C26<=6.4,"Prediabetes","Diabetes")) -> Normal
A27: Id26 | B27: 33.88 | C27: 7.01 | D27: No | E27: No | F27: No | G27: 3 | H27: Yes | I27: =IF(B27<18.5,"under Weight",IF(B27<=24.9,"Normal Weight",IF(B27<=29.9,"Over Weight","Obesity"))) -> Obesity | J27: =IF(C27<5.7,"Normal",IF(C27<=6.4,"Prediabetes","Diabetes")) -> Diabetes
A28: Id27 | B28: 30.875 | C28: 11.88 | D28: No | E28: No | F28: No | G28: 0 | H28: Yes | I28: =IF(B28<18.5,"under Weight",IF(B28<=24.9,"Normal Weight",IF(B28<=29.9,"Over Weight","Obesity"))) -> Obesity | J28: =IF(C28<5.7,"Normal",IF(C28<=6.4,"Prediabetes","Diabetes")) -> Diabetes
A29: Id28 | B29: 36.86 | C29: 5.19 | D29: Yes | E29: No | F29: Yes | G29: 1 | H29: Yes | I29: =IF(B29<18.5,"under Weight",IF(B29<=24.9,"Normal Weight",IF(B29<=29.9,"Over Weight","Obesity"))) -> Obesity | J29: =IF(C29<5.7,"Normal",IF(C29<=6.4,"Prediabetes","Diabetes")) -> Normal
... A2336: Id2335 | B2336: 17.58 | C2336: 4.51 | D2336: No | E2336: No | F2336: No | G2336: 1 | H2336: No | I2336: =IF(B2336<18.5,"under Weight",IF(B2336<=24.9,"Normal Weight",IF(B2336<=29.9,"Over Weight","Obesity"))) -> under Weight | J2336: =IF(C2336<5.7,"Normal",IF(C2336<=6.4,"Prediabetes","Diabetes")) -> Normal

Sheet Health Care
A1: Customer ID | B1: First Name | C1: BMI | D1: HBA1C | E1: Heart Issues | F1: Any Transplants | G1: Cancer history | H1: NumberOfMajorSurgeries | I1: smoker | J1: Weight Status | K1: Diabets Status | L1: charges | M1: Hospital tier | N1: City tier | O1: State ID | P1: Date Of Birth | Q1: Age
A2: Id1 | B2: =VLOOKUP(A2,'Customer Names'!A1:D2336,2,0) -> Hawks | C2: {=VLOOKUP('Health Care'!A2,'Medical Examinations'!A1:J2336,{2,3,4,5,6,7,8,9,10},0)} -> 47.41 | D2: 7.47 | E2: No | F2: No | G2: No | H2: 0 | I2: Yes | J2: Obesity | K2: Diabetes | L2: {=VLOOKUP(A2,'Hospitalisation Details'!$A$1:$K$2344,{6,7,8,9,10,11},0)} -> 63770.43 | M2: tier - 1 | N2: tier - 3 | O2: R1013 | P2: 12-Oct-1968 | Q2: 54.655556
A3: Id2 | B3: =VLOOKUP(A3,'Customer Names'!A2:D2337,2,0) -> Lehner | C3: {=VLOOKUP('Health Care'!A3,'Medical Examinations'!A2:J2337,{2,3,4,5,6,7,8,9,10},0)} -> 30.36 | D3: 5.77 | E3: No | F3: No | G3: No | H3: 0 | I3: Yes | J3: Obesity | K3: Prediabetes | L3: {=VLOOKUP(A3,'Hospitalisation Details'!$A$1:$K$2344,{6,7,8,9,10,11},0)} -> 62592.87 | M3: tier - 2 | N3: tier - 3 | O3: R1013 | P3: 8-Jun-1977 | Q3: 46
A4: Id3 | B4: =VLOOKUP(A4,'Customer Names'!A3:D2338,2,0) -> Lu | C4: {=VLOOKUP('Health Care'!A4,'Medical Examinations'!A3:J2338,{2,3,4,5,6,7,8,9,10},0)} -> 34.485 | D4: 11.87 | E4: Yes | F4: No | G4: No | H4: 2 | I4: Yes | J4: Obesity | K4: Diabetes | L4: {=VLOOKUP(A4,'Hospitalisation Details'!$A$1:$K$2344,{6,7,8,9,10,11},0)} -> 60021.4 | M4: tier - 1 | N4: tier - 1 | O4: R1012 | P4: 11-Sep-1970 | Q4: 52.741667
A5: Id4 | B5: =VLOOKUP(A5,'Customer Names'!A4:D2339,2,0) -> Osborne | C5: {=VLOOKUP('Health Care'!A5,'Medical Examinations'!A4:J2339,{2,3,4,5,6,7,8,9,10},0)} -> 38.095 | D5: 6.05 | E5: No | F5: No | G5: No | H5: 0 | I5: Yes | J5: Obesity | K5: Prediabetes | L5: {=VLOOKUP(A5,'Hospitalisation Details'!$A$1:$K$2344,{6,7,8,9,10,11},0)} -> 58571.07 | M5: tier - 1 | N5: tier - 3 | O5: R1024 | P5: 6-Jun-1991 | Q5: 32.005556
A6: Id5 | B6: =VLOOKUP(A6,'Customer Names'!A5:D2340,2,0) -> Kadala | C6: {=VLOOKUP('Health Care'!A6,'Medical Examinations'!A5:J2340,{2,3,4,5,6,7,8,9,10},0)} -> 35.53 | D6: 5.45 | E6: No | F6: No | G6: No | H6: 0 | I6: Yes | J6: Obesity | K6: Normal | L6: {=VLOOKUP(A6,'Hospitalisation Details'!$A$1:$K$2344,{6,7,8,9,10,11},0)} -> 55135.4 | M6: tier - 1 | N6: tier - 2 | O6: R1012 | P6: 19-Jun-1989 | Q6: 33.969444
A7: Id6 | B7: =VLOOKUP(A7,'Customer Names'!A6:D2341,2,0) -> Baker | C7: {=VLOOKUP('Health Care'!A7,'Medical Examinations'!A6:J2341,{2,3,4,5,6,7,8,9,10},0)} -> 32.8 | D7: 6.59 | E7: No | F7: No | G7: No | H7: 0 | I7: Yes | J7: Obesity | K7: Diabetes | L7: {=VLOOKUP(A7,'Hospitalisation Details'!$A$1:$K$2344,{6,7,8,9,10,11},0)} -> 52590.83 | M7: tier - 1 | N7: tier - 3 | O7: R1011 | P7: 4-Aug-1962 | Q7: 60.844444
A8: Id7 | B8: =VLOOKUP(A8,'Customer Names'!A7:D2342,2,0) -> Macpherson | C8: {=VLOOKUP('Health Care'!A8,'Medical Examinations'!A7:J2342,{2,3,4,5,6,7,8,9,10},0)} -> 36.4 | D8: 6.07 | E8: No | F8: No | G8: No | H8: 0 | I8: Yes | J8: Obesity | K8: Prediabetes | L8: {=VLOOKUP(A8,'Hospitalisation Details'!$A$1:$K$2344,{6,7,8,9,10,11},0)} -> 51194.56 | M8: tier - 1 | N8: tier - 3 | O8: R1011 | P8: 27-Oct-1994 | Q8: 28.613889
A9: Id8 | B9: =VLOOKUP(A9,'Customer Names'!A8:D2343,2,0) -> Hallman | C9: {=VLOOKUP('Health Care'!A9,'Medical Examinations'!A8:J2343,{2,3,4,5,6,7,8,9,10},0)} -> 36.96 | D9: 7.93 | E9: No | F9: No | G9: No | H9: 3 | I9: Yes | J9: Obesity | K9: Diabetes | L9: {=VLOOKUP(A9,'Hospitalisation Details'!$A$1:$K$2344,{6,7,8,9,10,11},0)} -> 49577.66 | M9: tier - 2 | N9: tier - 2 | O9: R1013 | P9: 27-Jun-1958 | Q9: 64.947222
A10: Id9 | B10: =VLOOKUP(A10,'Customer Names'!A9:D2344,2,0) -> Moran | C10: {=VLOOKUP('Health Care'!A10,'Medical Examinations'!A9:J2344,{2,3,4,5,6,7,8,9,10},0)} -> 41.14 | D10: 9.58 | E10: Yes | F10: No | G10: Yes | H10: 1 | I10: Yes | J10: Obesity | K10: Diabetes | L10: {=VLOOKUP(A10,'Hospitalisation Details'!$A$1:$K$2344,{6,7,8,9,10,11},0)} -> 48970.25 | M10: tier - 1 | N10: tier - 2 | O10: R1013 | P10: 4-Sep-1963 | Q10: 59.761111
A11: Id10 | B11: =VLOOKUP(A11,'Customer Names'!A10:D2345,2,0) -> Benner | C11: {=VLOOKUP('Health Care'!A11,'Medical Examinations'!A10:J2345,{2,3,4,5,6,7,8,9,10},0)} -> 38.06 | D11: 10.79 | E11: No | F11: No | G11: No | H11: 0 | I11: Yes | J11: Obesity | K11: Diabetes | L11: {=VLOOKUP(A11,'Hospitalisation Details'!$A$1:$K$2344,{6,7,8,9,10,11},0)} -> 48885.14 | M11: tier - 1 | N11: tier - 2 | O11: R1013 | P11: 29-Dec-1978 | Q11: 44.441667
A12: Id11 | B12: =VLOOKUP(A12,'Customer Names'!A11:D2346,2,0) -> Fierro Vargas | C12: {=VLOOKUP('Health Care'!A12,'Medical Examinations'!A11:J2346,{2,3,4,5,6,7,8,9,10},0)} -> 37.7 | D12: 5.96 | E12: Yes | F12: No | G12: No | H12: 2 | I12: Yes | J12: Obesity | K12: Prediabetes | L12: {=VLOOKUP(A12,'Hospitalisation Details'!$A$1:$K$2344,{6,7,8,9,10,11},0)} -> 48824.45 | M12: tier - 2 | N12: tier - 1 | O12: R1011 | P12: 22-Jul-1959 | Q12: 63.877778
A13: Id12 | B13: =VLOOKUP(A13,'Customer Names'!A12:D2347,2,0) -> Franz | C13: {=VLOOKUP('Health Care'!A13,'Medical Examinations'!A12:J2347,{2,3,4,5,6,7,8,9,10},0)} -> 42.13 | D13: 11.9 | E13: No | F13: No | G13: No | H13: 0 | I13: Yes | J13: Obesity | K13: Diabetes | L13: {=VLOOKUP(A13,'Hospitalisation Details'!$A$1:$K$2344,{6,7,8,9,10,11},0)} -> 48675.52 | M13: tier - 1 | N13: tier - 2 | O13: R1013 | P13: 27-Oct-1965 | Q13: 57.613889
... A2336: Id2335 | B2336: =VLOOKUP(A2336,'Customer Names'!A2335:D4670,2,0) -> German | C2336: {=VLOOKUP('Health Care'!A2336,'Medical Examinations'!A2335:J4670,{2,3,4,5,6,7,8,9,10},0)} -> 17.58 | D2336: 4.51 | E2336: No | F2336: No | G2336: No | H2336: 1 | I2336: No | J2336: under Weight | K2336: Normal | L2336: {=VLOOKUP(A2336,'Hospitalisation Details'!$A$1:$K$2344,{6,7,8,9,10,11},0)} -> 563.84 | M2336: tier - 2 | N2336: tier - 3 | O2336: R1013 | P2336: 9-Jul-1992 | Q2336: 30.913889

Sheet Cancer history chart 
A1: smoker | B1: (All)
A3: Row Labels | B3: Count of Customer ID
A4: No | B4: 363
A5: Yes | B5: 68
A6: Grand Total | B6: 431
A16: Distribution of cancer history among smokers and non-smokers

Sheet transplant chart
A2: Total number of major surgeries and average HbA1C differ between patients with and without a history of transplants
A4: Row Labels | B4: Sum of NumberOfMajorSurgeries | C4: Average of HBA1C
A5: No | B5: 236 | C5: 6.5685012
A6: Yes | B6: 26 | C6: 5.1366667
A7: Grand Total | B7: 262 | C7: 6.4887703

Sheet diabetes chart
A3: Sum of charges | B3: Column Labels
A4: Row Labels | B4: Diabetes | C4: Normal | D4: Prediabetes | E4: Grand Total
A5: Normal Weight | B5: 1726354.5 | C5: 1674180.5 | D5: 841586.97 | E5: 4242122
A6: Grand Total | B6: 1726354.5 | C6: 1674180.5 | D6: 841586.97 | E6: 4242122
A25: Healthcare charges vary based on different weight statuses and diabetes statuses

Sheet hospital chart
A3: Average of charges | B3: Column Labels
A4: Row Labels | B4: tier - 1 | C4: tier - 2 | D4: tier - 3 | E4: Grand Total
A5: R1011 | B5: 26774.072 | C5: 14881.851 | D5: 6911.7608 | E5: 15289.734
A6: R1012 | B6: 20969.12 | C6: 9234.7312 | D6: 9657.3261 | E6: 9889.3891
A7: R1013 | B7: 16950.201 | C7: 6177.7274 | D7: 6713.9953 | E7: 6739.5199
A8: R1014 | C8: 2395.17 | D8: 22412.65 | E8: 12403.91
A9: R1015 | C9: 11028.98 | E9: 11028.98
A10: R1016 | C10: 10145.207 | D10: 8360.4275 | E10: 9125.3329
A11: R1017 | B11: 26486.95 | C11: 9391.2017 | D11: 9102.986 | E11: 11910.465
A12: R1018 | C12: 1704.7 | D12: 13747.87 | E12: 7726.285
A13: R1019 | C13: 5309.274 | D13: 21259.38 | E13: 7967.625
A14: R1023 | C14: 14451.84 | E14: 14451.84
A15: R1024 | B15: 19785.87 | C15: 10335.935 | D15: 15050.606 | E15: 11994.111
A16: Grand Total | B16: 23530.479 | C16: 8734.9508 | D16: 8442.3246 | E16: 9854.1722
B23: compare the average charges for each hospital tier within different states

Sheet bmi and hb1ac chart
C2: Correlation between age and both BMI and HbA1C
C4: Row Labels | D4: Average of BMI | E4: Average of HBA1C
C5: 18-20 | D5: 21.813485 | E5: 5.2721212
C6: 20-22 | D6: 21.814231 | E6: 7.1973077
C7: 22-24 | D7: 22.209444 | E7: 5.1466667
C8: 24-26 | D8: 22.686818 | E8: 5.2854545
C9: 26-28 | D9: 21.494762 | E9: 4.8628571
C10: 30-32 | D10: 21.768125 | E10: 4.975
C11: 32-34 | D11: 22.24775 | E11: 5.1905
C12: 34-36 | D12: 21.527 | E12: 5.6085
C13: 36-38 | D13: 22.122333 | E13: 6.4773333
C14: 38-40 | D14: 22.390682 | E14: 5.4759091
C15: 40-42 | D15: 21.962778 | E15: 7.2555556
C16: 42-44 | D16: 22.257647 | E16: 5.0582353
... C28: Grand Total | D28: 22.034805 | E28: 6.5588049

Sheet age and charges chart
A1: relationship between age and healthcare charges.
A3: Row Labels | B3: Sum of charges
A4: 18-20 | B4: 89880.75
A5: 20-22 | B5: 125527.48
A6: 22-24 | B6: 110630.66
A7: 24-26 | B7: 120146.38
A8: 26-28 | B8: 123406.66
A9: 28-30 | B9: 160057.23
A10: 30-32 | B10: 127051.6
A11: 32-34 | B11: 276878.96
A12: 34-36 | B12: 156032.21
A13: 36-38 | B13: 148005.35
A14: 38-40 | B14: 221506.56
A15: 40-42 | B15: 215281.63
... A28: Grand Total | B28: 4242122

Sheet Dashboard
